[32m I [0m|2023-07-12 19:09:51 1689206991190432| MyApp:Server running on port 8787
type was not specified
determined type








































































































































































































































































































































































































































































































































































































































































































































































































































































































































































































































Traceback (most recent call last):
  File "/data-buddy/producers/file_parser/finance/../file_parser.py", line 106, in <module>
    check_success(c.put(row['category'], row['key'], row['value']))
  File "/data-buddy/producers/file_parser/../../service/api-libs/service_api_lib.py", line 9, in check_success
    assert(res.status_code == 200)
AssertionError
/db-create-buddy hit
/db-create-client hit
/db-create-category hit
/db-list-clients hit
/db-create-client hit
/db-list-categories hit
/db-put hit
/db-add-client hit
/db-list-clients hit
/db-connect-client hit
/db-list-categories hit
/db-put hit
Validation failed, here is why: At /transaction_type of "sugar" - instance not found in required enum

type was not specified
determined type








































































































































































































































































































































































































































































































































































































































































































































































































































































































































































































































Traceback (most recent call last):
  File "/data-buddy/producers/file_parser/finance/../file_parser.py", line 106, in <module>
    check_success(c.put(row['category'], row['key'], row['value']))
  File "/data-buddy/producers/file_parser/../../service/api-libs/service_api_lib.py", line 9, in check_success
    assert(res.status_code == 200)
AssertionError
Traceback (most recent call last):
  File "file_parser_reg_tester.py", line 100, in <module>
    raise Exception('File parser failed')
Exception: File parser failed
[TEST] fake_intuit_mint_data.csv
Something really went wrong
